<sdf version='1.7'>
  <model name='segway'>
    <link name='base_footprint'>
      <inertial>
        <pose>0 0 1.32994 0 -0 0</pose>
        <mass>80.005</mass>
        <inertia>
          <ixx>0.0212318</ixx>
          <ixy>0</ixy>
          <ixz>0</ixz>
          <iyy>0.0177018</iyy>
          <iyz>0</iyz>
          <izz>0.00439902</izz>
        </inertia>
      </inertial>
      <collision name='base_footprint_fixed_joint_lump__base_link_collision'>
        <pose>0 0 0 0 -0 0</pose>
        <geometry>
          <mesh>
            <scale>1 1 1</scale>
            <uri>model://segway/meshes/STL/base/body.stl</uri>
          </mesh>
        </geometry>
        <surface>
          <contact>
            <ode/>
          </contact>
          <friction>
            <ode>
              <mu>0.05</mu>
              <mu2>0.05</mu2>
            </ode>
          </friction>
        </surface>
      </collision>
      <visual name='base_footprint_fixed_joint_lump__base_link_visual'>
        <pose>0 0 0 0 -0 0</pose>
        <geometry>
          <mesh>
            <scale>1 1 1</scale>
            <uri>model://segway/meshes/DAE/base/body.dae</uri>
          </mesh>
        </geometry>
      </visual>
      <self_collide>0</self_collide>
      <gravity>1</gravity>
      <sensor name='imu_sensor' type='imu'>
        <always_on>1</always_on>
        <update_rate>100</update_rate>
        <visualize>1</visualize>
        <topic>__default_topic__</topic>
        <plugin name='imu_plugin' filename='libgazebo_ros_imu_sensor.so'>
          <topicName>imu</topicName>
          <update_rate>0</update_rate>
          <bodyName>imu_link</bodyName>
          <updateRateHZ>15.0</updateRateHZ>
          <gaussianNoise>0.0</gaussianNoise>
          <xyzOffset>0 0 0</xyzOffset>
          <rpyOffset>0 0 0</rpyOffset>
          <frameName>base_link</frameName>
          <initial_orientation_as_reference>0</initial_orientation_as_reference>
        </plugin>
        <pose>0 0 0.297322 0 -0 0</pose>
      </sensor>
    </link>
    <joint name='left_wheel_joint' type='revolute'>
      <pose relative_to='base_footprint'>0 -0.238506 0.297322 0 0 -3.14159</pose>
      <parent>base_footprint</parent>
      <child>left_wheel_link</child>
      <axis>
        <xyz>0 -1 0</xyz>
        <limit>
          <lower>-1e+16</lower>
          <upper>1e+16</upper>
        </limit>
        <dynamics>
          <spring_reference>0</spring_reference>
          <spring_stiffness>0</spring_stiffness>
        </dynamics>
      </axis>
    </joint>
    <link name='left_wheel_link'>
      <pose relative_to='left_wheel_joint'>0 0 0 0 -0 0</pose>
      <inertial>
        <pose>0 0.106 0 0 -0 0</pose>
        <mass>0.5</mass>
        <inertia>
          <ixx>0.00119</ixx>
          <ixy>0</ixy>
          <ixz>0</ixz>
          <iyy>0.0022</iyy>
          <iyz>0</iyz>
          <izz>0.00119</izz>
        </inertia>
      </inertial>
      <collision name='left_wheel_link_collision'>
        <pose>0 0 0 0 -0 0</pose>
        <geometry>
          <mesh>
            <scale>1 1 1</scale>
            <uri>model://segway/meshes/STL/wheel/wheel_sim.stl</uri>
          </mesh>
        </geometry>
        <surface>
          <contact>
            <ode/>
          </contact>
          <friction>
            <ode>
              <mu>0.8</mu>
              <mu2>0.8</mu2>
            </ode>
          </friction>
        </surface>
      </collision>
      <visual name='left_wheel_link_visual'>
        <pose>0 0 0 0 -0 0</pose>
        <geometry>
          <mesh>
            <scale>1 1 1</scale>
            <uri>model://segway/meshes/DAE/wheel/wheel_sim.dae</uri>
          </mesh>
        </geometry>
      </visual>
      <self_collide>0</self_collide>
    </link>
    <joint name='right_wheel_joint' type='revolute'>
      <pose relative_to='base_footprint'>0 0.238506 0.297322 0 -0 0</pose>
      <parent>base_footprint</parent>
      <child>right_wheel_link</child>
      <axis>
        <xyz>0 1 0</xyz>
        <limit>
          <lower>-1e+16</lower>
          <upper>1e+16</upper>
        </limit>
        <dynamics>
          <spring_reference>0</spring_reference>
          <spring_stiffness>0</spring_stiffness>
        </dynamics>
      </axis>
    </joint>
    <link name='right_wheel_link'>
      <pose relative_to='right_wheel_joint'>0 0 0 0 -0 0</pose>
      <inertial>
        <pose>0 0.106 0 0 -0 0</pose>
        <mass>0.5</mass>
        <inertia>
          <ixx>0.00119</ixx>
          <ixy>0</ixy>
          <ixz>0</ixz>
          <iyy>0.0022</iyy>
          <iyz>0</iyz>
          <izz>0.00119</izz>
        </inertia>
      </inertial>
      <collision name='right_wheel_link_collision'>
        <pose>0 0 0 0 -0 0</pose>
        <geometry>
          <mesh>
            <scale>1 1 1</scale>
            <uri>model://segway/meshes/STL/wheel/wheel_sim.stl</uri>
          </mesh>
        </geometry>
        <surface>
          <contact>
            <ode/>
          </contact>
          <friction>
            <ode>
              <mu>0.8</mu>
              <mu2>0.8</mu2>
            </ode>
          </friction>
        </surface>
      </collision>
      <visual name='right_wheel_link_visual'>
        <pose>0 0 0 0 -0 0</pose>
        <geometry>
          <mesh>
            <scale>1 1 1</scale>
            <uri>model://segway/meshes/DAE/wheel/wheel_sim.dae</uri>
          </mesh>
        </geometry>
      </visual>
      <self_collide>0</self_collide>
    </link>
    <static>0</static>
    <plugin name='gazebo_ros_control' filename='libgazebo_ros_control.so'>
      <robotNamespace>/segway</robotNamespace>
      <robotParam>/segway</robotParam>
      <robotSimType>gazebo_ros_control/DefaultRobotHWSim</robotSimType>
    </plugin>
    <plugin name='differential_drive_controller' filename='libgazebo_ros_diff_drive.so'>
      <ros>
        <namespace>/segway</namespace>
      </ros>
      <left_joint>left_wheel_joint</left_joint>
      <right_joint>right_wheel_joint</right_joint>
      <wheel_separation>0.66</wheel_separation>
      <wheel_diameter>0.56</wheel_diameter>
      <max_wheel_torque>10.0</max_wheel_torque>
      <max_wheel_acceleration>10.0</max_wheel_acceleration>
      <publish_odom>1</publish_odom>
      <publish_odom_tf>1</publish_odom_tf>
      <odometry_frame>odom</odometry_frame>
      <robot_base_frame>base_link</robot_base_frame>
    </plugin>
  </model>
</sdf>
