<?xml version="1.0" ?>
<!-- =================================================================================== -->
<!-- |    This document was autogenerated by xacro from cart_pole.urdf.xacro           | -->
<!-- |    EDITING THIS FILE BY HAND IS NOT RECOMMENDED                                 | -->
<!-- =================================================================================== -->
<robot name="segway">
  <!-- =============== Link & Joint =============== -->
  <!-- Base -->
  <link name="base_footprint"/>
  <joint name="base_link_joint" type="fixed">
    <origin xyz="0 0 0"/>
    <parent link="base_footprint"/>
    <child link="base_link"/>
  </joint>
  <link name="base_link">
    <visual>
      <geometry>
        <mesh filename="package://robot_description/meshes/STL/base/body.stl"/>
      </geometry>
    </visual>
    <collision>
      <geometry>
        <mesh filename="package://robot_description/meshes/STL/base/body.stl"/>
      </geometry>
    </collision>
    <inertial>
      <origin xyz="0 0 1.33"/>
      <mass value="80.0"/>
      <inertia ixx="0.0159" ixy="0" ixz="0" iyy="0.01237" iyz="0" izz="0.004399"/>
    </inertial>
  </link>
  <joint name="right_wheel_joint" type="continuous">
    <origin rpy="0 0 0" xyz="0 0.238506 0.297322"/>
    <parent link="base_link"/>
    <child link="right_wheel_link"/>
    <axis xyz="0 1 0"/>
  </joint>
  <link name="right_wheel_link">
    <visual>
      <geometry>
        <mesh filename="package://robot_description/meshes/STL/wheel/wheel_sim.stl"/>
      </geometry>
    </visual>
    <collision>
      <geometry>
        <mesh filename="package://robot_description/meshes/STL/wheel/wheel_sim.stl"/>
      </geometry>
    </collision>
    <inertial>
      <origin xyz="0 0.106 0"/>
      <mass value="0.5"/>
      <inertia ixx="0.00119" ixy="0" ixz="0" iyy="0.0022" iyz="0" izz="0.00119"/>
    </inertial>
  </link>
  <joint name="left_wheel_joint" type="continuous">
    <origin rpy="0 0 3.14159274" xyz="0 -0.238506 0.297322"/>
    <parent link="base_link"/>
    <child link="left_wheel_link"/>
    <axis xyz="0 -1 0"/>
  </joint>
  <link name="left_wheel_link">
    <visual>
      <geometry>
        <mesh filename="package://robot_description/meshes/STL/wheel/wheel_sim.stl"/>
      </geometry>
    </visual>
    <collision>
      <geometry>
        <mesh filename="package://robot_description/meshes/STL/wheel/wheel_sim.stl"/>
      </geometry>
    </collision>
    <inertial>
      <origin xyz="0 0.106 0"/>
      <mass value="0.5"/>
      <inertia ixx="0.00119" ixy="0" ixz="0" iyy="0.0022" iyz="0" izz="0.00119"/>
    </inertial>
  </link>
  <joint name="imu_joint" type="fixed">
    <origin rpy="0 0 0" xyz="0 0 0.297322"/>
    <parent link="base_link"/>
    <child link="imu_link"/>
  </joint>
  <link name="imu_link">
    <!--
	  <visual>
		<geometry>
		  <mesh filename="package://omni_robot_description/meshes/DAE/IMU/IMU_sensor.dae"/>
		</geometry>
	  </visual>
	  -->
    <inertial>
      <origin xyz="0 0 0"/>
      <mass value="0.005"/>
      <inertia ixx="1.67e-8" ixy="0" ixz="0" iyy="1.67e-8" iyz="0" izz="1.67e-8"/>
    </inertial>
  </link>
</robot>
